Workbook

Sheet สรุปภาพรวมและสถิติ
B2: รายงานสรุปและสถิติทะเบียนประชากร หมู่ที่ 8
B3: ข้อมูลสรุปประชากร 17 หลังคาเรือน รวม 69 คน | ปรับปรุงข้อมูล ณ วันที่ 3 กันยายน 2569
B5: ประชากรทั้งหมด | D5: มีชีวิต / เสียชีวิต | F5: ชาย / หญิง | H5: จำนวนบ้านเรือน / เจ้าบ้าน
B6: =COUNTA('ทะเบียนประชากร'!D5:D73) | D6: =COUNTIF('ทะเบียนประชากร'!J5:J73, "มีชีวิต") & " / " & COUNTIF('ทะเบียนประชากร'!J5:J73, "เสียชีวิต") & " คน" | F6: =COUNTIF('ทะเบียนประชากร'!E5:E73, "ชาย") & " / " & COUNTIF('ทะเบียนประชากร'!E5:E73, "หญิง") & " คน" | H6: =COUNTA('สรุปตามบ้านเลขที่'!A5:A21) & " หลัง / " & COUNTIF('ทะเบียนประชากร'!I5:I73, "เจ้าบ้าน") & " คน"
B9: ตารางที่ 1: โครงสร้างประชากรจำแนกตามช่วงวัย
B10: ช่วงวัย | C10: ช่วงอายุ (ปี) | D10: จำนวน (คน) | E10: ร้อยละ | F10: ชาย (คน) | G10: หญิง (คน)
B11: เด็กเล็ก (0–5 ปี) | C11: 0–5 | D11: =COUNTIF('ทะเบียนประชากร'!$H$5:$H$73, B11) | E11: =D11/$D$19 | F11: =COUNTIFS('ทะเบียนประชากร'!$H$5:$H$73, B11, 'ทะเบียนประชากร'!$E$5:$E$73, "ชาย") | G11: =COUNTIFS('ทะเบียนประชากร'!$H$5:$H$73, B11, 'ทะเบียนประชากร'!$E$5:$E$73, "หญิง")
B12: เด็กวัยเรียน (6–12 ปี) | C12: 6–12 | D12: =COUNTIF('ทะเบียนประชากร'!$H$5:$H$73, B12) | E12: =D12/$D$19 | F12: =COUNTIFS('ทะเบียนประชากร'!$H$5:$H$73, B12, 'ทะเบียนประชากร'!$E$5:$E$73, "ชาย") | G12: =COUNTIFS('ทะเบียนประชากร'!$H$5:$H$73, B12, 'ทะเบียนประชากร'!$E$5:$E$73, "หญิง")
B13: วัยรุ่น (13–17 ปี) | C13: 13–17 | D13: =COUNTIF('ทะเบียนประชากร'!$H$5:$H$73, B13) | E13: =D13/$D$19 | F13: =COUNTIFS('ทะเบียนประชากร'!$H$5:$H$73, B13, 'ทะเบียนประชากร'!$E$5:$E$73, "ชาย") | G13: =COUNTIFS('ทะเบียนประชากร'!$H$5:$H$73, B13, 'ทะเบียนประชากร'!$E$5:$E$73, "หญิง")
B14: วัยหนุ่มสาว (18–24 ปี) | C14: 18–24 | D14: =COUNTIF('ทะเบียนประชากร'!$H$5:$H$73, B14) | E14: =D14/$D$19 | F14: =COUNTIFS('ทะเบียนประชากร'!$H$5:$H$73, B14, 'ทะเบียนประชากร'!$E$5:$E$73, "ชาย") | G14: =COUNTIFS('ทะเบียนประชากร'!$H$5:$H$73, B14, 'ทะเบียนประชากร'!$E$5:$E$73, "หญิง")
B15: วัยทำงานตอนต้น (25–39 ปี) | C15: 25–39 | D15: =COUNTIF('ทะเบียนประชากร'!$H$5:$H$73, B15) | E15: =D15/$D$19 | F15: =COUNTIFS('ทะเบียนประชากร'!$H$5:$H$73, B15, 'ทะเบียนประชากร'!$E$5:$E$73, "ชาย") | G15: =COUNTIFS('ทะเบียนประชากร'!$H$5:$H$73, B15, 'ทะเบียนประชากร'!$E$5:$E$73, "หญิง")
B16: วัยทำงานตอนกลาง (40–59 ปี) | C16: 40–59 | D16: =COUNTIF('ทะเบียนประชากร'!$H$5:$H$73, B16) | E16: =D16/$D$19 | F16: =COUNTIFS('ทะเบียนประชากร'!$H$5:$H$73, B16, 'ทะเบียนประชากร'!$E$5:$E$73, "ชาย") | G16: =COUNTIFS('ทะเบียนประชากร'!$H$5:$H$73, B16, 'ทะเบียนประชากร'!$E$5:$E$73, "หญิง")
B17: ผู้สูงอายุ (60 ปีขึ้นไป) | C17: 60+ | D17: =COUNTIF('ทะเบียนประชากร'!$H$5:$H$73, B17) | E17: =D17/$D$19 | F17: =COUNTIFS('ทะเบียนประชากร'!$H$5:$H$73, B17, 'ทะเบียนประชากร'!$E$5:$E$73, "ชาย") | G17: =COUNTIFS('ทะเบียนประชากร'!$H$5:$H$73, B17, 'ทะเบียนประชากร'!$E$5:$E$73, "หญิง")
B18: ไม่ระบุอายุปัจจุบัน | C18: เสียชีวิต | D18: =COUNTIF('ทะเบียนประชากร'!$H$5:$H$73, B18) | E18: =D18/$D$19 | F18: =COUNTIFS('ทะเบียนประชากร'!$H$5:$H$73, B18, 'ทะเบียนประชากร'!$E$5:$E$73, "ชาย") | G18: =COUNTIFS('ทะเบียนประชากร'!$H$5:$H$73, B18, 'ทะเบียนประชากร'!$E$5:$E$73, "หญิง")
B19: รวมทั้งสิ้น | C19: — | D19: =SUM(D11:D18) | E19: =SUM(E11:E18) | F19: =SUM(F11:F18) | G19: =SUM(G11:G18)
B22: สัดส่วนประชากรจำแนกตามเพศ | E22: สถานภาพการมีชีวิต
B23: เพศ | C23: จำนวน (คน) | E23: สถานะ | F23: จำนวน (คน)
B24: ชาย | C24: =COUNTIF('ทะเบียนประชากร'!$E$5:$E$73, "ชาย") | E24: มีชีวิต | F24: =COUNTIF('ทะเบียนประชากร'!$J$5:$J$73, "มีชีวิต")
B25: หญิง | C25: =COUNTIF('ทะเบียนประชากร'!$E$5:$E$73, "หญิง") | E25: เสียชีวิต | F25: =COUNTIF('ทะเบียนประชากร'!$J$5:$J$73, "เสียชีวิต")
J28: ข้อสังเกตและข้อมูลสำคัญประจำหมู่บ้าน
J29: 1. บ้านเรือนที่มีประชากรสูงสุด: บ้านเลขที่ 2 (9 คน), บ้านเลขที่ 43 (8 คน), บ้านเลขที่ 62 (7 คน)
J30: 2. โครงสร้างประชากรผู้สูงอายุ: มีผู้สูงอายุ (60 ปีขึ้นไป) จำนวน 19 คน คิดเป็นร้อยละ 27.5 ของประชากรทั้งหมด
J31: 3. กลุ่มวัยแรงงาน: วัยทำงาน (25–59 ปี) มีจำนวนรวม 33 คน คิดเป็นร้อยละ 47.8 ของประชากรทั้งหมด
J32: 4. วัยเด็กและเยาวชน: อายุ 0–17 ปี มีจำนวนรวม 8 คน คิดเป็นร้อยละ 11.6 ของประชากรทั้งหมด
J33: 5. สถานะบ้านเรือน: มีเจ้าบ้านลงทะเบียนชัดเจน 16 หลังคาเรือน (ยกเว้นบ้านเลขที่ 55 มีเฉพาะผู้อาศัย)
J34: 6. ผู้เสียชีวิตในระบบทะเบียน: มีจำนวน 2 คน (บ้านเลขที่ 44 และ 56)

Sheet ทะเบียนประชากร
A1: ทะเบียนข้อมูลประชากรตามบ้านเลขที่ หมู่ 8
A2: ข้อมูลรวบรวมและยืนยันล่าสุด | อ้างอิงอายุ ณ วันที่ 3 กันยายน 2569
A4: บ้านเลขที่ | B4: ลำดับ | C4: เลขประจำตัวประชาชน | D4: ชื่อ–นามสกุล | E4: เพศ | F4: วัน/เดือน/ปีเกิด | G4: อายุ (ปี) | H4: ช่วงวัย | I4: สถานภาพในบ้าน | J4: สถานะบุคคล | K4: ประเภทวันเกิด
A5: 2 | B5: 1 | C5: 3-1012-02664-20-6 | D5: นางสาวกุหลาบ น้ำจันทน์ | E5: หญิง | F5: พ.ศ. 2485 | G5: 84 | H5: =IF(J5="เสียชีวิต", "ไม่ระบุอายุปัจจุบัน", IF(ISBLANK(G5), "ไม่ระบุอายุปัจจุบัน", IF(G5<=5, "เด็กเล็ก (0–5 ปี)", IF(G5<=12, "เด็กวัยเรียน (6–12 ปี)", IF(G5<=17, "วัยรุ่น (13–17 ปี)", IF(G5<=24, "วัยหนุ่มสาว (18–24 ปี)", IF(G5<=39, "วัยทำงานตอนต้น (25–39 ปี)", IF(G5<=59, "วัยทำงานตอนกลาง (40–59 ปี)", "ผู้สูงอายุ (60 ปีขึ้นไป)")))))))) | I5: เจ้าบ้าน | J5: มีชีวิต | K5: ทราบเฉพาะปี
A6: 2 | B6: 2 | C6: 5-1301-99024-93-6 | D6: นายสมยศ ธาระเลิศ | E6: ชาย | F6: 19/08/2502 | G6: 67 | H6: =IF(J6="เสียชีวิต", "ไม่ระบุอายุปัจจุบัน", IF(ISBLANK(G6), "ไม่ระบุอายุปัจจุบัน", IF(G6<=5, "เด็กเล็ก (0–5 ปี)", IF(G6<=12, "เด็กวัยเรียน (6–12 ปี)", IF(G6<=17, "วัยรุ่น (13–17 ปี)", IF(G6<=24, "วัยหนุ่มสาว (18–24 ปี)", IF(G6<=39, "วัยทำงานตอนต้น (25–39 ปี)", IF(G6<=59, "วัยทำงานตอนกลาง (40–59 ปี)", "ผู้สูงอายุ (60 ปีขึ้นไป)")))))))) | I6: ผู้อาศัย | J6: มีชีวิต | K6: วัน/เดือน/ปีครบ
A7: 2 | B7: 3 | C7: 3-1012-02664-25-7 | D7: นาง ณภัค เศรษฐอังกูร | E7: หญิง | F7: 08/10/2505 | G7: 63 | H7: =IF(J7="เสียชีวิต", "ไม่ระบุอายุปัจจุบัน", IF(ISBLANK(G7), "ไม่ระบุอายุปัจจุบัน", IF(G7<=5, "เด็กเล็ก (0–5 ปี)", IF(G7<=12, "เด็กวัยเรียน (6–12 ปี)", IF(G7<=17, "วัยรุ่น (13–17 ปี)", IF(G7<=24, "วัยหนุ่มสาว (18–24 ปี)", IF(G7<=39, "วัยทำงานตอนต้น (25–39 ปี)", IF(G7<=59, "วัยทำงานตอนกลาง (40–59 ปี)", "ผู้สูงอายุ (60 ปีขึ้นไป)")))))))) | I7: ผู้อาศัย | J7: มีชีวิต | K7: วัน/เดือน/ปีครบ
A8: 2 | B8: 4 | C8: 3-1012-02664-33-8 | D8: นายพรชัย ชัยมี | E8: ชาย | F8: 12/03/2501 | G8: 68 | H8: =IF(J8="เสียชีวิต", "ไม่ระบุอายุปัจจุบัน", IF(ISBLANK(G8), "ไม่ระบุอายุปัจจุบัน", IF(G8<=5, "เด็กเล็ก (0–5 ปี)", IF(G8<=12, "เด็กวัยเรียน (6–12 ปี)", IF(G8<=17, "วัยรุ่น (13–17 ปี)", IF(G8<=24, "วัยหนุ่มสาว (18–24 ปี)", IF(G8<=39, "วัยทำงานตอนต้น (25–39 ปี)", IF(G8<=59, "วัยทำงานตอนกลาง (40–59 ปี)", "ผู้สูงอายุ (60 ปีขึ้นไป)")))))))) | I8: ผู้อาศัย | J8: มีชีวิต | K8: วัน/เดือน/ปีครบ
A9: 2 | B9: 5 | C9: 3-1012-05064-37-1 | D9: นางหทัยรัตน์ เปรมอำพล | E9: หญิง | F9: 06/03/2501 | G9: 68 | H9: =IF(J9="เสียชีวิต", "ไม่ระบุอายุปัจจุบัน", IF(ISBLANK(G9), "ไม่ระบุอายุปัจจุบัน", IF(G9<=5, "เด็กเล็ก (0–5 ปี)", IF(G9<=12, "เด็กวัยเรียน (6–12 ปี)", IF(G9<=17, "วัยรุ่น (13–17 ปี)", IF(G9<=24, "วัยหนุ่มสาว (18–24 ปี)", IF(G9<=39, "วัยทำงานตอนต้น (25–39 ปี)", IF(G9<=59, "วัยทำงานตอนกลาง (40–59 ปี)", "ผู้สูงอายุ (60 ปีขึ้นไป)")))))))) | I9: ผู้อาศัย | J9: มีชีวิต | K9: วัน/เดือน/ปีครบ
A10: 2 | B10: 6 | C10: 1-1007-01112-40-6 | D10: นายธัชกฤช เศรษฐอังกูร | E10: ชาย | F10: 25/11/2532 | G10: 36 | H10: =IF(J10="เสียชีวิต", "ไม่ระบุอายุปัจจุบัน", IF(ISBLANK(G10), "ไม่ระบุอายุปัจจุบัน", IF(G10<=5, "เด็กเล็ก (0–5 ปี)", IF(G10<=12, "เด็กวัยเรียน (6–12 ปี)", IF(G10<=17, "วัยรุ่น (13–17 ปี)", IF(G10<=24, "วัยหนุ่มสาว (18–24 ปี)", IF(G10<=39, "วัยทำงานตอนต้น (25–39 ปี)", IF(G10<=59, "วัยทำงานตอนกลาง (40–59 ปี)", "ผู้สูงอายุ (60 ปีขึ้นไป)")))))))) | I10: ผู้อาศัย | J10: มีชีวิต | K10: วัน/เดือน/ปีครบ
A11: 2 | B11: 7 | C11: 1-2503-00133-27-4 | D11: นางสาวสิริยากร ธาระเลิศ | E11: หญิง | F11: 15/05/2545 | G11: 24 | H11: =IF(J11="เสียชีวิต", "ไม่ระบุอายุปัจจุบัน", IF(ISBLANK(G11), "ไม่ระบุอายุปัจจุบัน", IF(G11<=5, "เด็กเล็ก (0–5 ปี)", IF(G11<=12, "เด็กวัยเรียน (6–12 ปี)", IF(G11<=17, "วัยรุ่น (13–17 ปี)", IF(G11<=24, "วัยหนุ่มสาว (18–24 ปี)", IF(G11<=39, "วัยทำงานตอนต้น (25–39 ปี)", IF(G11<=59, "วัยทำงานตอนกลาง (40–59 ปี)", "ผู้สูงอายุ (60 ปีขึ้นไป)")))))))) | I11: ผู้อาศัย | J11: มีชีวิต | K11: วัน/เดือน/ปีครบ
A12: 2 | B12: 8 | C12: 3-1012-02664-29-0 | D12: นางสาววัชรา ชัยมี | E12: หญิง | F12: 12/11/2507 | G12: 61 | H12: =IF(J12="เสียชีวิต", "ไม่ระบุอายุปัจจุบัน", IF(ISBLANK(G12), "ไม่ระบุอายุปัจจุบัน", IF(G12<=5, "เด็กเล็ก (0–5 ปี)", IF(G12<=12, "เด็กวัยเรียน (6–12 ปี)", IF(G12<=17, "วัยรุ่น (13–17 ปี)", IF(G12<=24, "วัยหนุ่มสาว (18–24 ปี)", IF(G12<=39, "วัยทำงานตอนต้น (25–39 ปี)", IF(G12<=59, "วัยทำงานตอนกลาง (40–59 ปี)", "ผู้สูงอายุ (60 ปีขึ้นไป)")))))))) | I12: ผู้อาศัย | J12: มีชีวิต | K12: วัน/เดือน/ปีครบ
A13: 2 | B13: 9 | C13: 3-6101-00094-63-4 | D13: นายสุริยา มณีไสย | E13: ชาย | F13: 06/05/2521 | G13: 48 | H13: =IF(J13="เสียชีวิต", "ไม่ระบุอายุปัจจุบัน", IF(ISBLANK(G13), "ไม่ระบุอายุปัจจุบัน", IF(G13<=5, "เด็กเล็ก (0–5 ปี)", IF(G13<=12, "เด็กวัยเรียน (6–12 ปี)", IF(G13<=17, "วัยรุ่น (13–17 ปี)", IF(G13<=24, "วัยหนุ่มสาว (18–24 ปี)", IF(G13<=39, "วัยทำงานตอนต้น (25–39 ปี)", IF(G13<=59, "วัยทำงานตอนกลาง (40–59 ปี)", "ผู้สูงอายุ (60 ปีขึ้นไป)")))))))) | I13: ผู้อาศัย | J13: มีชีวิต | K13: วัน/เดือน/ปีครบ
A14: 25 | B14: 1 | C14: 3-9201-00123-32-1 | D14: นายเชื้อ ทองรักษ์ | E14: ชาย | F14: 23/08/2490 | G14: 79 | H14: =IF(J14="เสียชีวิต", "ไม่ระบุอายุปัจจุบัน", IF(ISBLANK(G14), "ไม่ระบุอายุปัจจุบัน", IF(G14<=5, "เด็กเล็ก (0–5 ปี)", IF(G14<=12, "เด็กวัยเรียน (6–12 ปี)", IF(G14<=17, "วัยรุ่น (13–17 ปี)", IF(G14<=24, "วัยหนุ่มสาว (18–24 ปี)", IF(G14<=39, "วัยทำงานตอนต้น (25–39 ปี)", IF(G14<=59, "วัยทำงานตอนกลาง (40–59 ปี)", "ผู้สูงอายุ (60 ปีขึ้นไป)")))))))) | I14: เจ้าบ้าน | J14: มีชีวิต | K14: วัน/เดือน/ปีครบ
A15: 25 | B15: 2 | C15: 3-2603-00235-32-4 | D15: น.ส. บังอร ธรรมศีล | E15: หญิง | F15: 27/08/2510 | G15: 59 | H15: =IF(J15="เสียชีวิต", "ไม่ระบุอายุปัจจุบัน", IF(ISBLANK(G15), "ไม่ระบุอายุปัจจุบัน", IF(G15<=5, "เด็กเล็ก (0–5 ปี)", IF(G15<=12, "เด็กวัยเรียน (6–12 ปี)", IF(G15<=17, "วัยรุ่น (13–17 ปี)", IF(G15<=24, "วัยหนุ่มสาว (18–24 ปี)", IF(G15<=39, "วัยทำงานตอนต้น (25–39 ปี)", IF(G15<=59, "วัยทำงานตอนกลาง (40–59 ปี)", "ผู้สูงอายุ (60 ปีขึ้นไป)")))))))) | I15: ผู้อาศัย | J15: มีชีวิต | K15: วัน/เดือน/ปีครบ
A16: 25 | B16: 3 | C16: 1-2699-00266-89-3 | D16: นายอรรถพล ทองรักษ์ | E16: ชาย | F16: 03/12/2540 | G16: 28 | H16: =IF(J16="เสียชีวิต", "ไม่ระบุอายุปัจจุบัน", IF(ISBLANK(G16), "ไม่ระบุอายุปัจจุบัน", IF(G16<=5, "เด็กเล็ก (0–5 ปี)", IF(G16<=12, "เด็กวัยเรียน (6–12 ปี)", IF(G16<=17, "วัยรุ่น (13–17 ปี)", IF(G16<=24, "วัยหนุ่มสาว (18–24 ปี)", IF(G16<=39, "วัยทำงานตอนต้น (25–39 ปี)", IF(G16<=59, "วัยทำงานตอนกลาง (40–59 ปี)", "ผู้สูงอายุ (60 ปีขึ้นไป)")))))))) | I16: ผู้อาศัย | J16: มีชีวิต | K16: วัน/เดือน/ปีครบ
... A35: 44 | B35: 1 | C35: 1-1043-00570-92-0 | D35: นายวีรพันธุ แก้วประดับ | E35: ชาย | F35: 04/12/2545 | G35: 23 | H35: =IF(J35="เสียชีวิต", "ไม่ระบุอายุปัจจุบัน", IF(ISBLANK(G35), "ไม่ระบุอายุปัจจุบัน", IF(G35<=5, "เด็กเล็ก (0–5 ปี)", IF(G35<=12, "เด็กวัยเรียน (6–12 ปี)", IF(G35<=17, "วัยรุ่น (13–17 ปี)", IF(G35<=24, "วัยหนุ่มสาว (18–24 ปี)", IF(G35<=39, "วัยทำงานตอนต้น (25–39 ปี)", IF(G35<=59, "วัยทำงานตอนกลาง (40–59 ปี)", "ผู้สูงอายุ (60 ปีขึ้นไป)")))))))) | I35: เจ้าบ้าน | J35: มีชีวิต | K35: วัน/เดือน/ปีครบ
A36: 44 | B36: 2 | C36: 3-2603-00417-00-7 | D36: นายวีรพงษ์ แก้วประดับ | E36: ชาย | F36: 18/08/2524 | G36: — | H36: =IF(J36="เสียชีวิต", "ไม่ระบุอายุปัจจุบัน", IF(ISBLANK(G36), "ไม่ระบุอายุปัจจุบัน", IF(G36<=5, "เด็กเล็ก (0–5 ปี)", IF(G36<=12, "เด็กวัยเรียน (6–12 ปี)", IF(G36<=17, "วัยรุ่น (13–17 ปี)", IF(G36<=24, "วัยหนุ่มสาว (18–24 ปี)", IF(G36<=39, "วัยทำงานตอนต้น (25–39 ปี)", IF(G36<=59, "วัยทำงานตอนกลาง (40–59 ปี)", "ผู้สูงอายุ (60 ปีขึ้นไป)")))))))) | I36: ผู้อาศัย | J36: เสียชีวิต | K36: วัน/เดือน/ปีครบ
A37: 44 | B37: 3 | C37: 1-2603-00075-39-8 | D37: นายสุชาติ แก้วประดับ | E37: ชาย | F37: 29/10/2533 | G37: 35 | H37: =IF(J37="เสียชีวิต", "ไม่ระบุอายุปัจจุบัน", IF(ISBLANK(G37), "ไม่ระบุอายุปัจจุบัน", IF(G37<=5, "เด็กเล็ก (0–5 ปี)", IF(G37<=12, "เด็กวัยเรียน (6–12 ปี)", IF(G37<=17, "วัยรุ่น (13–17 ปี)", IF(G37<=24, "วัยหนุ่มสาว (18–24 ปี)", IF(G37<=39, "วัยทำงานตอนต้น (25–39 ปี)", IF(G37<=59, "วัยทำงานตอนกลาง (40–59 ปี)", "ผู้สูงอายุ (60 ปีขึ้นไป)")))))))) | I37: ผู้อาศัย | J37: มีชีวิต | K37: วัน/เดือน/ปีครบ
A38: 44 | B38: 4 | C38: 1-3399-00295-11-6 | D38: น.ส. นิตยา สิทโธ | E38: หญิง | F38: 28/04/2536 | G38: 33 | H38: =IF(J38="เสียชีวิต", "ไม่ระบุอายุปัจจุบัน", IF(ISBLANK(G38), "ไม่ระบุอายุปัจจุบัน", IF(G38<=5, "เด็กเล็ก (0–5 ปี)", IF(G38<=12, "เด็กวัยเรียน (6–12 ปี)", IF(G38<=17, "วัยรุ่น (13–17 ปี)", IF(G38<=24, "วัยหนุ่มสาว (18–24 ปี)", IF(G38<=39, "วัยทำงานตอนต้น (25–39 ปี)", IF(G38<=59, "วัยทำงานตอนกลาง (40–59 ปี)", "ผู้สูงอายุ (60 ปีขึ้นไป)")))))))) | I38: ผู้อาศัย | J38: มีชีวิต | K38: วัน/เดือน/ปีครบ
A39: 44 | B39: 5 | C39: 3-3005-00058-80-8 | D39: น.ส. พะเยา โค้งนอก | E39: หญิง | F39: 14/08/2519 | G39: 50 | H39: =IF(J39="เสียชีวิต", "ไม่ระบุอายุปัจจุบัน", IF(ISBLANK(G39), "ไม่ระบุอายุปัจจุบัน", IF(G39<=5, "เด็กเล็ก (0–5 ปี)", IF(G39<=12, "เด็กวัยเรียน (6–12 ปี)", IF(G39<=17, "วัยรุ่น (13–17 ปี)", IF(G39<=24, "วัยหนุ่มสาว (18–24 ปี)", IF(G39<=39, "วัยทำงานตอนต้น (25–39 ปี)", IF(G39<=59, "วัยทำงานตอนกลาง (40–59 ปี)", "ผู้สูงอายุ (60 ปีขึ้นไป)")))))))) | I39: ผู้อาศัย | J39: มีชีวิต | K39: วัน/เดือน/ปีครบ
A40: 49 | B40: 1 | C40: 3-2603-00083-28-1 | D40: นายจงรักษ์ เจริญนา | E40: ชาย | F40: 21/04/2515 | G40: 54 | H40: =IF(J40="เสียชีวิต", "ไม่ระบุอายุปัจจุบัน", IF(ISBLANK(G40), "ไม่ระบุอายุปัจจุบัน", IF(G40<=5, "เด็กเล็ก (0–5 ปี)", IF(G40<=12, "เด็กวัยเรียน (6–12 ปี)", IF(G40<=17, "วัยรุ่น (13–17 ปี)", IF(G40<=24, "วัยหนุ่มสาว (18–24 ปี)", IF(G40<=39, "วัยทำงานตอนต้น (25–39 ปี)", IF(G40<=59, "วัยทำงานตอนกลาง (40–59 ปี)", "ผู้สูงอายุ (60 ปีขึ้นไป)")))))))) | I40: เจ้าบ้าน | J40: มีชีวิต | K40: วัน/เดือน/ปีครบ
A41: 49 | B41: 2 | C41: 3-2603-00234-96-4 | D41: นางม้วน เจริญนา | E41: หญิง | F41: 08/01/2516 | G41: 53 | H41: =IF(J41="เสียชีวิต", "ไม่ระบุอายุปัจจุบัน", IF(ISBLANK(G41), "ไม่ระบุอายุปัจจุบัน", IF(G41<=5, "เด็กเล็ก (0–5 ปี)", IF(G41<=12, "เด็กวัยเรียน (6–12 ปี)", IF(G41<=17, "วัยรุ่น (13–17 ปี)", IF(G41<=24, "วัยหนุ่มสาว (18–24 ปี)", IF(G41<=39, "วัยทำงานตอนต้น (25–39 ปี)", IF(G41<=59, "วัยทำงานตอนกลาง (40–59 ปี)", "ผู้สูงอายุ (60 ปีขึ้นไป)")))))))) | I41: ผู้อาศัย | J41: มีชีวิต | K41: วัน/เดือน/ปีครบ
A42: 49 | B42: 3 | C42: 1-2603-00100-83-0 | D42: นายวรวัฒน์ เจริญนา | E42: ชาย | F42: 27/10/2538 | G42: 30 | H42: =IF(J42="เสียชีวิต", "ไม่ระบุอายุปัจจุบัน", IF(ISBLANK(G42), "ไม่ระบุอายุปัจจุบัน", IF(G42<=5, "เด็กเล็ก (0–5 ปี)", IF(G42<=12, "เด็กวัยเรียน (6–12 ปี)", IF(G42<=17, "วัยรุ่น (13–17 ปี)", IF(G42<=24, "วัยหนุ่มสาว (18–24 ปี)", IF(G42<=39, "วัยทำงานตอนต้น (25–39 ปี)", IF(G42<=59, "วัยทำงานตอนกลาง (40–59 ปี)", "ผู้สูงอายุ (60 ปีขึ้นไป)")))))))) | I42: ผู้อาศัย | J42: มีชีวิต | K42: วัน/เดือน/ปีครบ
A43: 49 | B43: 4 | C43: 1-2604-01295-14-8 | D43: ด.ช. ธวัชชัย เจริญนา | E43: ชาย | F43: 02/05/2558 | G43: 11 | H43: =IF(J43="เสียชีวิต", "ไม่ระบุอายุปัจจุบัน", IF(ISBLANK(G43), "ไม่ระบุอายุปัจจุบัน", IF(G43<=5, "เด็กเล็ก (0–5 ปี)", IF(G43<=12, "เด็กวัยเรียน (6–12 ปี)", IF(G43<=17, "วัยรุ่น (13–17 ปี)", IF(G43<=24, "วัยหนุ่มสาว (18–24 ปี)", IF(G43<=39, "วัยทำงานตอนต้น (25–39 ปี)", IF(G43<=59, "วัยทำงานตอนกลาง (40–59 ปี)", "ผู้สูงอายุ (60 ปีขึ้นไป)")))))))) | I43: ผู้อาศัย | J43: มีชีวิต | K43: วัน/เดือน/ปีครบ
A44: 49 | B44: 5 | C44: 1-2603-00087-46-9 | D44: นายวราวุฒิ เจริญนา | E44: ชาย | F44: 02/05/2536 | G44: 33 | H44: =IF(J44="เสียชีวิต", "ไม่ระบุอายุปัจจุบัน", IF(ISBLANK(G44), "ไม่ระบุอายุปัจจุบัน", IF(G44<=5, "เด็กเล็ก (0–5 ปี)", IF(G44<=12, "เด็กวัยเรียน (6–12 ปี)", IF(G44<=17, "วัยรุ่น (13–17 ปี)", IF(G44<=24, "วัยหนุ่มสาว (18–24 ปี)", IF(G44<=39, "วัยทำงานตอนต้น (25–39 ปี)", IF(G44<=59, "วัยทำงานตอนกลาง (40–59 ปี)", "ผู้สูงอายุ (60 ปีขึ้นไป)")))))))) | I44: ผู้อาศัย | J44: มีชีวิต | K44: วัน/เดือน/ปีครบ
A45: 54 | B45: 1 | C45: 3-2603-00233-62-3 | D45: นางสมจิตร แก้วประดับ | E45: หญิง | F45: 26/09/2501 | G45: 67 | H45: =IF(J45="เสียชีวิต", "ไม่ระบุอายุปัจจุบัน", IF(ISBLANK(G45), "ไม่ระบุอายุปัจจุบัน", IF(G45<=5, "เด็กเล็ก (0–5 ปี)", IF(G45<=12, "เด็กวัยเรียน (6–12 ปี)", IF(G45<=17, "วัยรุ่น (13–17 ปี)", IF(G45<=24, "วัยหนุ่มสาว (18–24 ปี)", IF(G45<=39, "วัยทำงานตอนต้น (25–39 ปี)", IF(G45<=59, "วัยทำงานตอนกลาง (40–59 ปี)", "ผู้สูงอายุ (60 ปีขึ้นไป)")))))))) | I45: เจ้าบ้าน | J45: มีชีวิต | K45: วัน/เดือน/ปีครบ
A46: 54 | B46: 2 | C46: 1-2603-00001-44-1 | D46: น.ส. อาภาพร แก้วประดับ | E46: หญิง | F46: 03/02/2527 | G46: 42 | H46: =IF(J46="เสียชีวิต", "ไม่ระบุอายุปัจจุบัน", IF(ISBLANK(G46), "ไม่ระบุอายุปัจจุบัน", IF(G46<=5, "เด็กเล็ก (0–5 ปี)", IF(G46<=12, "เด็กวัยเรียน (6–12 ปี)", IF(G46<=17, "วัยรุ่น (13–17 ปี)", IF(G46<=24, "วัยหนุ่มสาว (18–24 ปี)", IF(G46<=39, "วัยทำงานตอนต้น (25–39 ปี)", IF(G46<=59, "วัยทำงานตอนกลาง (40–59 ปี)", "ผู้สูงอายุ (60 ปีขึ้นไป)")))))))) | I46: ผู้อาศัย | J46: มีชีวิต | K46: วัน/เดือน/ปีครบ
A47: 54 | B47: 3 | C47: 1-1015-00142-01-5 | D47: นาย นิตินัย แก้วประดับ | E47: ชาย | F47: 08/02/2529 | G47: 40 | H47: =IF(J47="เสียชีวิต", "ไม่ระบุอายุปัจจุบัน", IF(ISBLANK(G47), "ไม่ระบุอายุปัจจุบัน", IF(G47<=5, "เด็กเล็ก (0–5 ปี)", IF(G47<=12, "เด็กวัยเรียน (6–12 ปี)", IF(G47<=17, "วัยรุ่น (13–17 ปี)", IF(G47<=24, "วัยหนุ่มสาว (18–24 ปี)", IF(G47<=39, "วัยทำงานตอนต้น (25–39 ปี)", IF(G47<=59, "วัยทำงานตอนกลาง (40–59 ปี)", "ผู้สูงอายุ (60 ปีขึ้นไป)")))))))) | I47: ผู้อาศัย | J47: มีชีวิต | K47: วัน/เดือน/ปีครบ
A48: 55 | B48: 1 | C48: 3-2603-00233-70-4 | D48: นายสุเทพ แก้วประดับ | E48: ชาย | F48: 28/03/2526 | G48: 43 | H48: =IF(J48="เสียชีวิต", "ไม่ระบุอายุปัจจุบัน", IF(ISBLANK(G48), "ไม่ระบุอายุปัจจุบัน", IF(G48<=5, "เด็กเล็ก (0–5 ปี)", IF(G48<=12, "เด็กวัยเรียน (6–12 ปี)", IF(G48<=17, "วัยรุ่น (13–17 ปี)", IF(G48<=24, "วัยหนุ่มสาว (18–24 ปี)", IF(G48<=39, "วัยทำงานตอนต้น (25–39 ปี)", IF(G48<=59, "วัยทำงานตอนกลาง (40–59 ปี)", "ผู้สูงอายุ (60 ปีขึ้นไป)")))))))) | I48: ผู้อาศัย | J48: มีชีวิต | K48: วัน/เดือน/ปีครบ
... A50: 56 | B50: 1 | C50: 3-2603-00233-96-8 | D50: นายพยุงศักดิ์ เนื่องวงษ์ | E50: ชาย | F50: 23/05/2512 | G50: 57 | H50: =IF(J50="เสียชีวิต", "ไม่ระบุอายุปัจจุบัน", IF(ISBLANK(G50), "ไม่ระบุอายุปัจจุบัน", IF(G50<=5, "เด็กเล็ก (0–5 ปี)", IF(G50<=12, "เด็กวัยเรียน (6–12 ปี)", IF(G50<=17, "วัยรุ่น (13–17 ปี)", IF(G50<=24, "วัยหนุ่มสาว (18–24 ปี)", IF(G50<=39, "วัยทำงานตอนต้น (25–39 ปี)", IF(G50<=59, "วัยทำงานตอนกลาง (40–59 ปี)", "ผู้สูงอายุ (60 ปีขึ้นไป)")))))))) | I50: เจ้าบ้าน | J50: มีชีวิต | K50: วัน/เดือน/ปีครบ
A51: 56 | B51: 2 | C51: 3-2603-00178-27-4 | D51: นางทิพยา สมมูล | E51: หญิง | F51: 01/10/2511 | G51: — | H51: =IF(J51="เสียชีวิต", "ไม่ระบุอายุปัจจุบัน", IF(ISBLANK(G51), "ไม่ระบุอายุปัจจุบัน", IF(G51<=5, "เด็กเล็ก (0–5 ปี)", IF(G51<=12, "เด็กวัยเรียน (6–12 ปี)", IF(G51<=17, "วัยรุ่น (13–17 ปี)", IF(G51<=24, "วัยหนุ่มสาว (18–24 ปี)", IF(G51<=39, "วัยทำงานตอนต้น (25–39 ปี)", IF(G51<=59, "วัยทำงานตอนกลาง (40–59 ปี)", "ผู้สูงอายุ (60 ปีขึ้นไป)")))))))) | I51: ผู้อาศัย | J51: เสียชีวิต | K51: วัน/เดือน/ปีครบ
A52: 56 | B52: 3 | C52: 1-2603-00132-10-3 | D52: น.ส. วรรณา เพ็ชรแก้ว | E52: หญิง | F52: 01/02/2545 | G52: 24 | H52: =IF(J52="เสียชีวิต", "ไม่ระบุอายุปัจจุบัน", IF(ISBLANK(G52), "ไม่ระบุอายุปัจจุบัน", IF(G52<=5, "เด็กเล็ก (0–5 ปี)", IF(G52<=12, "เด็กวัยเรียน (6–12 ปี)", IF(G52<=17, "วัยรุ่น (13–17 ปี)", IF(G52<=24, "วัยหนุ่มสาว (18–24 ปี)", IF(G52<=39, "วัยทำงานตอนต้น (25–39 ปี)", IF(G52<=59, "วัยทำงานตอนกลาง (40–59 ปี)", "ผู้สูงอายุ (60 ปีขึ้นไป)")))))))) | I52: ผู้อาศัย | J52: มีชีวิต | K52: วัน/เดือน/ปีครบ
A53: 57 | B53: 1 | C53: 3-2603-00417-29-5 | D53: นายเขียน นาคะจะ | E53: ชาย | F53: 21/10/2503 | G53: 65 | H53: =IF(J53="เสียชีวิต", "ไม่ระบุอายุปัจจุบัน", IF(ISBLANK(G53), "ไม่ระบุอายุปัจจุบัน", IF(G53<=5, "เด็กเล็ก (0–5 ปี)", IF(G53<=12, "เด็กวัยเรียน (6–12 ปี)", IF(G53<=17, "วัยรุ่น (13–17 ปี)", IF(G53<=24, "วัยหนุ่มสาว (18–24 ปี)", IF(G53<=39, "วัยทำงานตอนต้น (25–39 ปี)", IF(G53<=59, "วัยทำงานตอนกลาง (40–59 ปี)", "ผู้สูงอายุ (60 ปีขึ้นไป)")))))))) | I53: เจ้าบ้าน | J53: มีชีวิต | K53: วัน/เดือน/ปีครบ
A54: 57 | B54: 2 | C54: 3-2603-00233-67-4 | D54: นางสมบัติ นาคะจะ | E54: หญิง | F54: 30/08/2503 | G54: 66 | H54: =IF(J54="เสียชีวิต", "ไม่ระบุอายุปัจจุบัน", IF(ISBLANK(G54), "ไม่ระบุอายุปัจจุบัน", IF(G54<=5, "เด็กเล็ก (0–5 ปี)", IF(G54<=12, "เด็กวัยเรียน (6–12 ปี)", IF(G54<=17, "วัยรุ่น (13–17 ปี)", IF(G54<=24, "วัยหนุ่มสาว (18–24 ปี)", IF(G54<=39, "วัยทำงานตอนต้น (25–39 ปี)", IF(G54<=59, "วัยทำงานตอนกลาง (40–59 ปี)", "ผู้สูงอายุ (60 ปีขึ้นไป)")))))))) | I54: ผู้อาศัย | J54: มีชีวิต | K54: วัน/เดือน/ปีครบ
A55: 57 | B55: 3 | C55: 3-2603-00417-33-3 | D55: นายสุรัตน์ นาคะจะ | E55: ชาย | F55: 24/05/2525 | G55: 44 | H55: =IF(J55="เสียชีวิต", "ไม่ระบุอายุปัจจุบัน", IF(ISBLANK(G55), "ไม่ระบุอายุปัจจุบัน", IF(G55<=5, "เด็กเล็ก (0–5 ปี)", IF(G55<=12, "เด็กวัยเรียน (6–12 ปี)", IF(G55<=17, "วัยรุ่น (13–17 ปี)", IF(G55<=24, "วัยหนุ่มสาว (18–24 ปี)", IF(G55<=39, "วัยทำงานตอนต้น (25–39 ปี)", IF(G55<=59, "วัยทำงานตอนกลาง (40–59 ปี)", "ผู้สูงอายุ (60 ปีขึ้นไป)")))))))) | I55: ผู้อาศัย | J55: มีชีวิต | K55: วัน/เดือน/ปีครบ
A56: 57 | B56: 4 | C56: 1-2699-00315-40-1 | D56: นายณรงค์ฤทธิ์ นาคะจะ | E56: ชาย | F56: 23/08/2543 | G56: 26 | H56: =IF(J56="เสียชีวิต", "ไม่ระบุอายุปัจจุบัน", IF(ISBLANK(G56), "ไม่ระบุอายุปัจจุบัน", IF(G56<=5, "เด็กเล็ก (0–5 ปี)", IF(G56<=12, "เด็กวัยเรียน (6–12 ปี)", IF(G56<=17, "วัยรุ่น (13–17 ปี)", IF(G56<=24, "วัยหนุ่มสาว (18–24 ปี)", IF(G56<=39, "วัยทำงานตอนต้น (25–39 ปี)", IF(G56<=59, "วัยทำงานตอนกลาง (40–59 ปี)", "ผู้สูงอายุ (60 ปีขึ้นไป)")))))))) | I56: ผู้อาศัย | J56: มีชีวิต | K56: วัน/เดือน/ปีครบ
A57: 57 | B57: 5 | C57: 1-1007-03754-54-5 | D57: น.ส. เกศรินทร์ นาคะจะ | E57: หญิง | F57: 01/08/2548 | G57: 21 | H57: =IF(J57="เสียชีวิต", "ไม่ระบุอายุปัจจุบัน", IF(ISBLANK(G57), "ไม่ระบุอายุปัจจุบัน", IF(G57<=5, "เด็กเล็ก (0–5 ปี)", IF(G57<=12, "เด็กวัยเรียน (6–12 ปี)", IF(G57<=17, "วัยรุ่น (13–17 ปี)", IF(G57<=24, "วัยหนุ่มสาว (18–24 ปี)", IF(G57<=39, "วัยทำงานตอนต้น (25–39 ปี)", IF(G57<=59, "วัยทำงานตอนกลาง (40–59 ปี)", "ผู้สูงอายุ (60 ปีขึ้นไป)")))))))) | I57: ผู้อาศัย | J57: มีชีวิต | K57: วัน/เดือน/ปีครบ
A58: 57 | B58: 6 | C58: 1-1043-01218-06-5 | D58: น.ส. ณัฎฐ์ประวีณา นาคะจะ | E58: หญิง | F58: 20/08/2552 | G58: 17 | H58: =IF(J58="เสียชีวิต", "ไม่ระบุอายุปัจจุบัน", IF(ISBLANK(G58), "ไม่ระบุอายุปัจจุบัน", IF(G58<=5, "เด็กเล็ก (0–5 ปี)", IF(G58<=12, "เด็กวัยเรียน (6–12 ปี)", IF(G58<=17, "วัยรุ่น (13–17 ปี)", IF(G58<=24, "วัยหนุ่มสาว (18–24 ปี)", IF(G58<=39, "วัยทำงานตอนต้น (25–39 ปี)", IF(G58<=59, "วัยทำงานตอนกลาง (40–59 ปี)", "ผู้สูงอายุ (60 ปีขึ้นไป)")))))))) | I58: ผู้อาศัย | J58: มีชีวิต | K58: วัน/เดือน/ปีครบ
A59: 62 | B59: 1 | C59: 3-1020-00751-33-8 | D59: นางรัตนา เวหะ | E59: หญิง | F59: 01/05/2498 | G59: 71 | H59: =IF(J59="เสียชีวิต", "ไม่ระบุอายุปัจจุบัน", IF(ISBLANK(G59), "ไม่ระบุอายุปัจจุบัน", IF(G59<=5, "เด็กเล็ก (0–5 ปี)", IF(G59<=12, "เด็กวัยเรียน (6–12 ปี)", IF(G59<=17, "วัยรุ่น (13–17 ปี)", IF(G59<=24, "วัยหนุ่มสาว (18–24 ปี)", IF(G59<=39, "วัยทำงานตอนต้น (25–39 ปี)", IF(G59<=59, "วัยทำงานตอนกลาง (40–59 ปี)", "ผู้สูงอายุ (60 ปีขึ้นไป)")))))))) | I59: เจ้าบ้าน | J59: มีชีวิต | K59: วัน/เดือน/ปีครบ
A60: 62 | B60: 2 | C60: 3-1020-00660-64-2 | D60: นางเอื้ออารี เสมหะ | E60: หญิง | F60: 27/08/2520 | G60: 49 | H60: =IF(J60="เสียชีวิต", "ไม่ระบุอายุปัจจุบัน", IF(ISBLANK(G60), "ไม่ระบุอายุปัจจุบัน", IF(G60<=5, "เด็กเล็ก (0–5 ปี)", IF(G60<=12, "เด็กวัยเรียน (6–12 ปี)", IF(G60<=17, "วัยรุ่น (13–17 ปี)", IF(G60<=24, "วัยหนุ่มสาว (18–24 ปี)", IF(G60<=39, "วัยทำงานตอนต้น (25–39 ปี)", IF(G60<=59, "วัยทำงานตอนกลาง (40–59 ปี)", "ผู้สูงอายุ (60 ปีขึ้นไป)")))))))) | I60: ผู้อาศัย | J60: มีชีวิต | K60: วัน/เดือน/ปีครบ
...

Sheet สรุปตามบ้านเลขที่
A1: สรุปข้อมูลจำแนกตามบ้านเลขที่ หมู่ 8
A2: จำนวนบ้านเรือนทั้งหมด 17 หลังคาเรือน
A4: บ้านเลขที่ | B4: เจ้าบ้าน | C4: จำนวนสมาชิก (คน) | D4: ชาย | E4: หญิง | F4: มีชีวิต | G4: เสียชีวิต | H4: สัดส่วนประชากร
A5: 2 | B5: นางสาวกุหลาบ น้ำจันทน์ | C5: =COUNTIF('ทะเบียนประชากร'!$A$5:$A$73, A5) | D5: =COUNTIFS('ทะเบียนประชากร'!$A$5:$A$73, A5, 'ทะเบียนประชากร'!$E$5:$E$73, "ชาย") | E5: =COUNTIFS('ทะเบียนประชากร'!$A$5:$A$73, A5, 'ทะเบียนประชากร'!$E$5:$E$73, "หญิง") | F5: =COUNTIFS('ทะเบียนประชากร'!$A$5:$A$73, A5, 'ทะเบียนประชากร'!$J$5:$J$73, "มีชีวิต") | G5: =COUNTIFS('ทะเบียนประชากร'!$A$5:$A$73, A5, 'ทะเบียนประชากร'!$J$5:$J$73, "เสียชีวิต") | H5: =C5/$C$22
A6: 25 | B6: นายเชื้อ ทองรักษ์ | C6: =COUNTIF('ทะเบียนประชากร'!$A$5:$A$73, A6) | D6: =COUNTIFS('ทะเบียนประชากร'!$A$5:$A$73, A6, 'ทะเบียนประชากร'!$E$5:$E$73, "ชาย") | E6: =COUNTIFS('ทะเบียนประชากร'!$A$5:$A$73, A6, 'ทะเบียนประชากร'!$E$5:$E$73, "หญิง") | F6: =COUNTIFS('ทะเบียนประชากร'!$A$5:$A$73, A6, 'ทะเบียนประชากร'!$J$5:$J$73, "มีชีวิต") | G6: =COUNTIFS('ทะเบียนประชากร'!$A$5:$A$73, A6, 'ทะเบียนประชากร'!$J$5:$J$73, "เสียชีวิต") | H6: =C6/$C$22
A7: 27 | B7: นายสุบิน โลกนิมิตร | C7: =COUNTIF('ทะเบียนประชากร'!$A$5:$A$73, A7) | D7: =COUNTIFS('ทะเบียนประชากร'!$A$5:$A$73, A7, 'ทะเบียนประชากร'!$E$5:$E$73, "ชาย") | E7: =COUNTIFS('ทะเบียนประชากร'!$A$5:$A$73, A7, 'ทะเบียนประชากร'!$E$5:$E$73, "หญิง") | F7: =COUNTIFS('ทะเบียนประชากร'!$A$5:$A$73, A7, 'ทะเบียนประชากร'!$J$5:$J$73, "มีชีวิต") | G7: =COUNTIFS('ทะเบียนประชากร'!$A$5:$A$73, A7, 'ทะเบียนประชากร'!$J$5:$J$73, "เสียชีวิต") | H7: =C7/$C$22
A8: 28 | B8: น.ส. สมคิด งามประเสริฐ | C8: =COUNTIF('ทะเบียนประชากร'!$A$5:$A$73, A8) | D8: =COUNTIFS('ทะเบียนประชากร'!$A$5:$A$73, A8, 'ทะเบียนประชากร'!$E$5:$E$73, "ชาย") | E8: =COUNTIFS('ทะเบียนประชากร'!$A$5:$A$73, A8, 'ทะเบียนประชากร'!$E$5:$E$73, "หญิง") | F8: =COUNTIFS('ทะเบียนประชากร'!$A$5:$A$73, A8, 'ทะเบียนประชากร'!$J$5:$J$73, "มีชีวิต") | G8: =COUNTIFS('ทะเบียนประชากร'!$A$5:$A$73, A8, 'ทะเบียนประชากร'!$J$5:$J$73, "เสียชีวิต") | H8: =C8/$C$22
A9: 38 | B9: นาง วันเพ็ญ สุขใจ | C9: =COUNTIF('ทะเบียนประชากร'!$A$5:$A$73, A9) | D9: =COUNTIFS('ทะเบียนประชากร'!$A$5:$A$73, A9, 'ทะเบียนประชากร'!$E$5:$E$73, "ชาย") | E9: =COUNTIFS('ทะเบียนประชากร'!$A$5:$A$73, A9, 'ทะเบียนประชากร'!$E$5:$E$73, "หญิง") | F9: =COUNTIFS('ทะเบียนประชากร'!$A$5:$A$73, A9, 'ทะเบียนประชากร'!$J$5:$J$73, "มีชีวิต") | G9: =COUNTIFS('ทะเบียนประชากร'!$A$5:$A$73, A9, 'ทะเบียนประชากร'!$J$5:$J$73, "เสียชีวิต") | H9: =C9/$C$22
A10: 43 | B10: นายบุญฤทธิ์ วาวิไลย | C10: =COUNTIF('ทะเบียนประชากร'!$A$5:$A$73, A10) | D10: =COUNTIFS('ทะเบียนประชากร'!$A$5:$A$73, A10, 'ทะเบียนประชากร'!$E$5:$E$73, "ชาย") | E10: =COUNTIFS('ทะเบียนประชากร'!$A$5:$A$73, A10, 'ทะเบียนประชากร'!$E$5:$E$73, "หญิง") | F10: =COUNTIFS('ทะเบียนประชากร'!$A$5:$A$73, A10, 'ทะเบียนประชากร'!$J$5:$J$73, "มีชีวิต") | G10: =COUNTIFS('ทะเบียนประชากร'!$A$5:$A$73, A10, 'ทะเบียนประชากร'!$J$5:$J$73, "เสียชีวิต") | H10: =C10/$C$22
A11: 44 | B11: นายวีรพันธุ แก้วประดับ | C11: =COUNTIF('ทะเบียนประชากร'!$A$5:$A$73, A11) | D11: =COUNTIFS('ทะเบียนประชากร'!$A$5:$A$73, A11, 'ทะเบียนประชากร'!$E$5:$E$73, "ชาย") | E11: =COUNTIFS('ทะเบียนประชากร'!$A$5:$A$73, A11, 'ทะเบียนประชากร'!$E$5:$E$73, "หญิง") | F11: =COUNTIFS('ทะเบียนประชากร'!$A$5:$A$73, A11, 'ทะเบียนประชากร'!$J$5:$J$73, "มีชีวิต") | G11: =COUNTIFS('ทะเบียนประชากร'!$A$5:$A$73, A11, 'ทะเบียนประชากร'!$J$5:$J$73, "เสียชีวิต") | H11: =C11/$C$22
A12: 49 | B12: นายจงรักษ์ เจริญนา | C12: =COUNTIF('ทะเบียนประชากร'!$A$5:$A$73, A12) | D12: =COUNTIFS('ทะเบียนประชากร'!$A$5:$A$73, A12, 'ทะเบียนประชากร'!$E$5:$E$73, "ชาย") | E12: =COUNTIFS('ทะเบียนประชากร'!$A$5:$A$73, A12, 'ทะเบียนประชากร'!$E$5:$E$73, "หญิง") | F12: =COUNTIFS('ทะเบียนประชากร'!$A$5:$A$73, A12, 'ทะเบียนประชากร'!$J$5:$J$73, "มีชีวิต") | G12: =COUNTIFS('ทะเบียนประชากร'!$A$5:$A$73, A12, 'ทะเบียนประชากร'!$J$5:$J$73, "เสียชีวิต") | H12: =C12/$C$22
A13: 54 | B13: นางสมจิตร แก้วประดับ | C13: =COUNTIF('ทะเบียนประชากร'!$A$5:$A$73, A13) | D13: =COUNTIFS('ทะเบียนประชากร'!$A$5:$A$73, A13, 'ทะเบียนประชากร'!$E$5:$E$73, "ชาย") | E13: =COUNTIFS('ทะเบียนประชากร'!$A$5:$A$73, A13, 'ทะเบียนประชากร'!$E$5:$E$73, "หญิง") | F13: =COUNTIFS('ทะเบียนประชากร'!$A$5:$A$73, A13, 'ทะเบียนประชากร'!$J$5:$J$73, "มีชีวิต") | G13: =COUNTIFS('ทะเบียนประชากร'!$A$5:$A$73, A13, 'ทะเบียนประชากร'!$J$5:$J$73, "เสียชีวิต") | H13: =C13/$C$22
A14: 55 | B14: ไม่มี (ผู้อาศัยอย่างเดียว) | C14: =COUNTIF('ทะเบียนประชากร'!$A$5:$A$73, A14) | D14: =COUNTIFS('ทะเบียนประชากร'!$A$5:$A$73, A14, 'ทะเบียนประชากร'!$E$5:$E$73, "ชาย") | E14: =COUNTIFS('ทะเบียนประชากร'!$A$5:$A$73, A14, 'ทะเบียนประชากร'!$E$5:$E$73, "หญิง") | F14: =COUNTIFS('ทะเบียนประชากร'!$A$5:$A$73, A14, 'ทะเบียนประชากร'!$J$5:$J$73, "มีชีวิต") | G14: =COUNTIFS('ทะเบียนประชากร'!$A$5:$A$73, A14, 'ทะเบียนประชากร'!$J$5:$J$73, "เสียชีวิต") | H14: =C14/$C$22
A15: 56 | B15: นายพยุงศักดิ์ เนื่องวงษ์ | C15: =COUNTIF('ทะเบียนประชากร'!$A$5:$A$73, A15) | D15: =COUNTIFS('ทะเบียนประชากร'!$A$5:$A$73, A15, 'ทะเบียนประชากร'!$E$5:$E$73, "ชาย") | E15: =COUNTIFS('ทะเบียนประชากร'!$A$5:$A$73, A15, 'ทะเบียนประชากร'!$E$5:$E$73, "หญิง") | F15: =COUNTIFS('ทะเบียนประชากร'!$A$5:$A$73, A15, 'ทะเบียนประชากร'!$J$5:$J$73, "มีชีวิต") | G15: =COUNTIFS('ทะเบียนประชากร'!$A$5:$A$73, A15, 'ทะเบียนประชากร'!$J$5:$J$73, "เสียชีวิต") | H15: =C15/$C$22
A16: 57 | B16: นายเขียน นาคะจะ | C16: =COUNTIF('ทะเบียนประชากร'!$A$5:$A$73, A16) | D16: =COUNTIFS('ทะเบียนประชากร'!$A$5:$A$73, A16, 'ทะเบียนประชากร'!$E$5:$E$73, "ชาย") | E16: =COUNTIFS('ทะเบียนประชากร'!$A$5:$A$73, A16, 'ทะเบียนประชากร'!$E$5:$E$73, "หญิง") | F16: =COUNTIFS('ทะเบียนประชากร'!$A$5:$A$73, A16, 'ทะเบียนประชากร'!$J$5:$J$73, "มีชีวิต") | G16: =COUNTIFS('ทะเบียนประชากร'!$A$5:$A$73, A16, 'ทะเบียนประชากร'!$J$5:$J$73, "เสียชีวิต") | H16: =C16/$C$22
... A21: 148 | B21: นายสมใจ แก้วประดับ | C21: =COUNTIF('ทะเบียนประชากร'!$A$5:$A$73, A21) | D21: =COUNTIFS('ทะเบียนประชากร'!$A$5:$A$73, A21, 'ทะเบียนประชากร'!$E$5:$E$73, "ชาย") | E21: =COUNTIFS('ทะเบียนประชากร'!$A$5:$A$73, A21, 'ทะเบียนประชากร'!$E$5:$E$73, "หญิง") | F21: =COUNTIFS('ทะเบียนประชากร'!$A$5:$A$73, A21, 'ทะเบียนประชากร'!$J$5:$J$73, "มีชีวิต") | G21: =COUNTIFS('ทะเบียนประชากร'!$A$5:$A$73, A21, 'ทะเบียนประชากร'!$J$5:$J$73, "เสียชีวิต") | H21: =C21/$C$22
A22: รวมทั้งสิ้น | B22: 17 หลังคาเรือน | C22: =SUM(C5:C21) | D22: =SUM(D5:D21) | E22: =SUM(E5:E21) | F22: =SUM(F5:F21) | G22: =SUM(G5:G21) | H22: =SUM(H5:H21)
